Workbook
Name Slicer_gender: #N/A

Sheet diagnoses_icd
A1: subject_id | B1: hadm_id | C1: seq_num | D1: icd_code | E1: icd_version
A2: 10035185 | B2: 22580999 | C2: 3 | D2: 4139 | E2: 9
A3: 10035185 | B3: 22580999 | C3: 10 | D3: V707 | E3: 9
A4: 10035185 | B4: 22580999 | C4: 1 | D4: 41401 | E4: 9
A5: 10035185 | B5: 22580999 | C5: 9 | D5: 3899 | E5: 9
A6: 10035185 | B6: 22580999 | C6: 11 | D6: V8532 | E6: 9
A7: 10035185 | B7: 22580999 | C7: 2 | D7: 25002 | E7: 9
A8: 10035185 | B8: 22580999 | C8: 7 | D8: 71696 | E8: 9
A9: 10035185 | B9: 22580999 | C9: 8 | D9: V1083 | E9: 9
A10: 10035185 | B10: 22580999 | C10: 4 | D10: 2724 | E10: 9
A11: 10035185 | B11: 22580999 | C11: 6 | D11: V5867 | E11: 9
A12: 10035185 | B12: 22580999 | C12: 5 | D12: 27800 | E12: 9
A13: 10009049 | B13: 22995465 | C13: 2 | D13: 4829 | E13: 9
... A4507: 10004733 | B4507: 27411876 | C4507: 29 | D4507: 30390 | E4507: 9

Sheet Mortality_Analysis
A3: Row Labels | B3: Average of hospital_expire_flag
A4: 70+ | B4: 0.13043478
A5: 50-70 | B5: 0.091836735
A6: Grand Total | B6: 0.099173554

Sheet top_diseases
A3: Row Labels | B3: Count of icd_code
A4: V1582 | B4: 5
A5: D696 | B5: 3
A6: K766 | B6: 2
A7: 0380 | B7: 2
A8: Z7902 | B8: 2
A9: 5849 | B9: 2
A10: I4892 | B10: 2
A11: N179 | B11: 2
A12: 486 | B12: 2
A13: 41400 | B13: 2
A14: V707 | B14: 2
A15: E119 | B15: 2
... A19: Grand Total | B19: 34

Sheet admissions
A1: subject_id | B1: hadm_id | C1: admittime | D1: dischtime | E1: deathtime | F1: admission_type | G1: admit_provider_id | H1: admission_location | I1: discharge_location | J1: insurance | K1: language | L1: marital_status | M1: race | N1: edregtime | O1: edouttime | P1: hospital_expire_flag | Q1: gender | R1: age | S1: age_group | T1: icd_code
A2: 10004235 | B2: 24181354 | C2: 108168.61 | D2: 108177.58 | F2: URGENT | G2: P03YMR | H2: TRANSFER FROM HOSPITAL | I2: SKILLED NURSING FACILITY | J2: Medicaid | K2: ENGLISH | L2: SINGLE | M2: BLACK/CAPE VERDEAN | N2: 108168.51 | O2: 108168.71 | P2: 0 | Q2: =_xlfn.XLOOKUP(A2, patients!A:A, patients!B:B) -> M | R2: =_xlfn.XLOOKUP(A2, patients!A:A, patients!C:C) -> 47 | S2: =IF(R2<30,"Under 30", IF(R2<=50,"30-50", IF(R2<=70,"50-70","70+"))) -> 30-50 | T2: =_xlfn.XLOOKUP(B2, diagnoses_icd!B:B, diagnoses_icd!D:D) -> 42731
A3: 10009628 | B3: 25926192 | C3: 92668.714 | D3: 92676.556 | F3: URGENT | G3: P41R5N | H3: TRANSFER FROM HOSPITAL | I3: HOME HEALTH CARE | J3: Medicaid | K3: ? | L3: MARRIED | M3: HISPANIC/LATINO - PUERTO RICAN | P3: 0 | Q3: =_xlfn.XLOOKUP(A3, patients!A:A, patients!B:B) -> M | R3: =_xlfn.XLOOKUP(A3, patients!A:A, patients!C:C) -> 58 | S3: =IF(R3<30,"Under 30", IF(R3<=50,"30-50", IF(R3<=70,"50-70","70+"))) -> 50-70 | T3: =_xlfn.XLOOKUP(B3, diagnoses_icd!B:B, diagnoses_icd!D:D) -> 36201
A4: 10018081 | B4: 23983182 | C4: 85698.085 | D4: 85703.816 | F4: URGENT | G4: P233F6 | H4: TRANSFER FROM HOSPITAL | I4: SKILLED NURSING FACILITY | J4: Medicare | K4: ENGLISH | L4: MARRIED | M4: WHITE | N4: 85697.683 | O4: 85698.135 | P4: 0 | Q4: =_xlfn.XLOOKUP(A4, patients!A:A, patients!B:B) -> M | R4: =_xlfn.XLOOKUP(A4, patients!A:A, patients!C:C) -> 79 | S4: =IF(R4<30,"Under 30", IF(R4<=50,"30-50", IF(R4<=70,"50-70","70+"))) -> 70+ | T4: =_xlfn.XLOOKUP(B4, diagnoses_icd!B:B, diagnoses_icd!D:D) -> V1582
A5: 10006053 | B5: 22942076 | C5: 77384.985 | D5: 77386.722 | E5: 77386.722 | F5: URGENT | G5: P38TI6 | H5: TRANSFER FROM HOSPITAL | I5: DIED | J5: Medicaid | K5: ENGLISH | M5: UNKNOWN | P5: 1 | Q5: =_xlfn.XLOOKUP(A5, patients!A:A, patients!B:B) -> M | R5: =_xlfn.XLOOKUP(A5, patients!A:A, patients!C:C) -> 52 | S5: =IF(R5<30,"Under 30", IF(R5<=50,"30-50", IF(R5<=70,"50-70","70+"))) -> 50-70 | T5: =_xlfn.XLOOKUP(B5, diagnoses_icd!B:B, diagnoses_icd!D:D) -> 45620
A6: 10031404 | B6: 21606243 | C6: 78014.782 | D6: 78016.873 | F6: URGENT | G6: P07HDB | H6: TRANSFER FROM HOSPITAL | I6: HOME | J6: Other | K6: ENGLISH | L6: WIDOWED | M6: WHITE | P6: 0 | Q6: =_xlfn.XLOOKUP(A6, patients!A:A, patients!B:B) -> F | R6: =_xlfn.XLOOKUP(A6, patients!A:A, patients!C:C) -> 82 | S6: =IF(R6<30,"Under 30", IF(R6<=50,"30-50", IF(R6<=70,"50-70","70+"))) -> 70+ | T6: =_xlfn.XLOOKUP(B6, diagnoses_icd!B:B, diagnoses_icd!D:D) -> E860
A7: 10005817 | B7: 20626031 | C7: 85084.072 | D7: 85092.628 | F7: URGENT | G7: P41R5N | H7: TRANSFER FROM HOSPITAL | I7: HOME HEALTH CARE | J7: Medicare | K7: ENGLISH | L7: MARRIED | M7: WHITE | P7: 0 | Q7: =_xlfn.XLOOKUP(A7, patients!A:A, patients!B:B) -> M | R7: =_xlfn.XLOOKUP(A7, patients!A:A, patients!C:C) -> 66 | S7: =IF(R7<30,"Under 30", IF(R7<=50,"30-50", IF(R7<=70,"50-70","70+"))) -> 50-70 | T7: =_xlfn.XLOOKUP(B7, diagnoses_icd!B:B, diagnoses_icd!D:D) -> V707
A8: 10019385 | B8: 20297618 | C8: 102315.85 | D8: 102325.57 | F8: URGENT | G8: P536JC | H8: TRANSFER FROM HOSPITAL | I8: HOME HEALTH CARE | J8: Other | K8: ENGLISH | L8: MARRIED | M8: WHITE | P8: 0 | Q8: =_xlfn.XLOOKUP(A8, patients!A:A, patients!B:B) -> M | R8: =_xlfn.XLOOKUP(A8, patients!A:A, patients!C:C) -> 44 | S8: =IF(R8<30,"Under 30", IF(R8<=50,"30-50", IF(R8<=70,"50-70","70+"))) -> 30-50 | T8: =_xlfn.XLOOKUP(B8, diagnoses_icd!B:B, diagnoses_icd!D:D) -> F17200
A9: 10002495 | B9: 24982426 | C9: 88167.845 | D9: 88174.737 | F9: URGENT | G9: P79SJ2 | H9: TRANSFER FROM HOSPITAL | I9: SKILLED NURSING FACILITY | J9: Medicare | K9: ENGLISH | L9: MARRIED | M9: UNKNOWN | P9: 0 | Q9: =_xlfn.XLOOKUP(A9, patients!A:A, patients!B:B) -> M | R9: =_xlfn.XLOOKUP(A9, patients!A:A, patients!C:C) -> 81 | S9: =IF(R9<30,"Under 30", IF(R9<=50,"30-50", IF(R9<=70,"50-70","70+"))) -> 70+ | T9: =_xlfn.XLOOKUP(B9, diagnoses_icd!B:B, diagnoses_icd!D:D) -> R310
A10: 10038081 | B10: 20755971 | C10: 78798.861 | D10: 78813 | E10: 78813.931 | F10: URGENT | G10: P48GIG | H10: TRANSFER FROM HOSPITAL | I10: DIED | J10: Other | K10: ? | L10: SINGLE | M10: UNKNOWN | P10: 1 | Q10: =_xlfn.XLOOKUP(A10, patients!A:A, patients!B:B) -> F | R10: =_xlfn.XLOOKUP(A10, patients!A:A, patients!C:C) -> 63 | S10: =IF(R10<30,"Under 30", IF(R10<=50,"30-50", IF(R10<=70,"50-70","70+"))) -> 50-70 | T10: =_xlfn.XLOOKUP(B10, diagnoses_icd!B:B, diagnoses_icd!D:D) -> 5187
A11: 10019917 | B11: 22585261 | C11: 103007.98 | D11: 103010.7 | F11: URGENT | G11: P3529J | H11: TRANSFER FROM HOSPITAL | I11: HOME | J11: Other | K11: ENGLISH | L11: SINGLE | M11: OTHER | P11: 0 | Q11: =_xlfn.XLOOKUP(A11, patients!A:A, patients!B:B) -> M | R11: =_xlfn.XLOOKUP(A11, patients!A:A, patients!C:C) -> 44 | S11: =IF(R11<30,"Under 30", IF(R11<=50,"30-50", IF(R11<=70,"50-70","70+"))) -> 30-50 | T11: =_xlfn.XLOOKUP(B11, diagnoses_icd!B:B, diagnoses_icd!D:D) -> 2851
A12: 10037861 | B12: 24256866 | C12: 78810.853 | D12: 78819.701 | F12: URGENT | G12: P64TGC | H12: TRANSFER FROM HOSPITAL | I12: HOME HEALTH CARE | J12: Medicare | K12: ENGLISH | L12: MARRIED | M12: UNKNOWN | P12: 0 | Q12: =_xlfn.XLOOKUP(A12, patients!A:A, patients!B:B) -> M | R12: =_xlfn.XLOOKUP(A12, patients!A:A, patients!C:C) -> 77 | S12: =IF(R12<30,"Under 30", IF(R12<=50,"30-50", IF(R12<=70,"50-70","70+"))) -> 70+ | T12: =_xlfn.XLOOKUP(B12, diagnoses_icd!B:B, diagnoses_icd!D:D) -> 41400
A13: 10026354 | B13: 24547356 | C13: 80288.299 | D13: 80299.521 | F13: URGENT | G13: P77BSD | H13: TRANSFER FROM HOSPITAL | I13: SKILLED NURSING FACILITY | J13: Other | K13: ? | M13: WHITE | N13: 80288.25 | O13: 80288.276 | P13: 0 | Q13: =_xlfn.XLOOKUP(A13, patients!A:A, patients!B:B) -> M | R13: =_xlfn.XLOOKUP(A13, patients!A:A, patients!C:C) -> 34 | S13: =IF(R13<30,"Under 30", IF(R13<=50,"30-50", IF(R13<=70,"50-70","70+"))) -> 30-50 | T13: =_xlfn.XLOOKUP(B13, diagnoses_icd!B:B, diagnoses_icd!D:D) -> D696
A14: 10015860 | B14: 26352758 | C14: 106920.39 | D14: 106924.83 | F14: URGENT | G14: P54RLA | H14: TRANSFER FROM SKILLED NURSING FACILITY | I14: SKILLED NURSING FACILITY | J14: Other | K14: ENGLISH | L14: SINGLE | M14: WHITE | N14: 106919.95 | O14: 106920.4 | P14: 0 | Q14: =_xlfn.XLOOKUP(A14, patients!A:A, patients!B:B) -> M | R14: =_xlfn.XLOOKUP(A14, patients!A:A, patients!C:C) -> 53 | S14: =IF(R14<30,"Under 30", IF(R14<=50,"30-50", IF(R14<=70,"50-70","70+"))) -> 50-70 | T14: =_xlfn.XLOOKUP(B14, diagnoses_icd!B:B, diagnoses_icd!D:D) -> E1142
A15: 10020740 | B15: 23831430 | C15: 91382.649 | D15: 91427.576 | F15: URGENT | G15: P7554I | H15: TRANSFER FROM HOSPITAL | I15: SKILLED NURSING FACILITY | J15: Other | K15: ENGLISH | L15: SINGLE | M15: WHITE | P15: 0 | Q15: =_xlfn.XLOOKUP(A15, patients!A:A, patients!B:B) -> M | R15: =_xlfn.XLOOKUP(A15, patients!A:A, patients!C:C) -> 56 | S15: =IF(R15<30,"Under 30", IF(R15<=50,"30-50", IF(R15<=70,"50-70","70+"))) -> 50-70 | T15: =_xlfn.XLOOKUP(B15, diagnoses_icd!B:B, diagnoses_icd!D:D) -> 2859
A16: 10012552 | B16: 27089790 | C16: 87741.721 | D16: 87749.59 | F16: URGENT | G16: P47E1G | H16: TRANSFER FROM HOSPITAL | I16: HOME HEALTH CARE | J16: Medicare | K16: ENGLISH | L16: MARRIED | M16: UNKNOWN | P16: 0 | Q16: =_xlfn.XLOOKUP(A16, patients!A:A, patients!B:B) -> M | R16: =_xlfn.XLOOKUP(A16, patients!A:A, patients!C:C) -> 78 | S16: =IF(R16<30,"Under 30", IF(R16<=50,"30-50", IF(R16<=70,"50-70","70+"))) -> 70+ | T16: =_xlfn.XLOOKUP(B16, diagnoses_icd!B:B, diagnoses_icd!D:D) -> 41401
A17: 10014354 | B17: 28335091 | C17: 90332.697 | D17: 90335.646 | F17: URGENT | G17: P79SJ2 | H17: TRANSFER FROM HOSPITAL | I17: HOME HEALTH CARE | J17: Other | K17: ENGLISH | L17: SINGLE | M17: WHITE | P17: 0 | Q17: =_xlfn.XLOOKUP(A17, patients!A:A, patients!B:B) -> M | R17: =_xlfn.XLOOKUP(A17, patients!A:A, patients!C:C) -> 60 | S17: =IF(R17<30,"Under 30", IF(R17<=50,"30-50", IF(R17<=70,"50-70","70+"))) -> 50-70 | T17: =_xlfn.XLOOKUP(B17, diagnoses_icd!B:B, diagnoses_icd!D:D) -> E119
A18: 10014354 | B18: 27487226 | C18: 90763.048 | D18: 90776.816 | F18: URGENT | G18: P44WVR | H18: TRANSFER FROM HOSPITAL | I18: HOME HEALTH CARE | J18: Other | K18: ENGLISH | L18: SINGLE | M18: WHITE | N18: 90762.879 | O18: 90763.102 | P18: 0 | Q18: =_xlfn.XLOOKUP(A18, patients!A:A, patients!B:B) -> M | R18: =_xlfn.XLOOKUP(A18, patients!A:A, patients!C:C) -> 60 | S18: =IF(R18<30,"Under 30", IF(R18<=50,"30-50", IF(R18<=70,"50-70","70+"))) -> 50-70 | T18: =_xlfn.XLOOKUP(B18, diagnoses_icd!B:B, diagnoses_icd!D:D) -> I4892
A19: 10039708 | B19: 25864431 | C19: 88475.256 | D19: 88491.875 | F19: URGENT | G19: P81KFM | H19: TRANSFER FROM HOSPITAL | I19: HOME HEALTH CARE | J19: Other | K19: ENGLISH | L19: SINGLE | M19: BLACK/AFRICAN AMERICAN | N19: 88474.932 | O19: 88475.339 | P19: 0 | Q19: =_xlfn.XLOOKUP(A19, patients!A:A, patients!B:B) -> F | R19: =_xlfn.XLOOKUP(A19, patients!A:A, patients!C:C) -> 46 | S19: =IF(R19<30,"Under 30", IF(R19<=50,"30-50", IF(R19<=70,"50-70","70+"))) -> 30-50 | T19: =_xlfn.XLOOKUP(B19, diagnoses_icd!B:B, diagnoses_icd!D:D) -> F17210
A20: 10000032 | B20: 22595853 | C20: 102396.93 | D20: 102397.72 | F20: URGENT | G20: P874LG | H20: TRANSFER FROM HOSPITAL | I20: HOME | J20: Other | K20: ENGLISH | L20: WIDOWED | M20: WHITE | N20: 102396.8 | O20: 102396.98 | P20: 0 | Q20: =_xlfn.XLOOKUP(A20, patients!A:A, patients!B:B) -> F | R20: =_xlfn.XLOOKUP(A20, patients!A:A, patients!C:C) -> 52 | S20: =IF(R20<30,"Under 30", IF(R20<=50,"30-50", IF(R20<=70,"50-70","70+"))) -> 50-70 | T20: =_xlfn.XLOOKUP(B20, diagnoses_icd!B:B, diagnoses_icd!D:D) -> 496
A21: 10020786 | B21: 23488445 | C21: 105717.53 | D21: 105721.72 | F21: URGENT | G21: P031HZ | H21: TRANSFER FROM HOSPITAL | I21: HOME | J21: Medicare | K21: ENGLISH | L21: WIDOWED | M21: WHITE | P21: 0 | Q21: =_xlfn.XLOOKUP(A21, patients!A:A, patients!B:B) -> F | R21: =_xlfn.XLOOKUP(A21, patients!A:A, patients!C:C) -> 86 | S21: =IF(R21<30,"Under 30", IF(R21<=50,"30-50", IF(R21<=70,"50-70","70+"))) -> 70+ | T21: =_xlfn.XLOOKUP(B21, diagnoses_icd!B:B, diagnoses_icd!D:D) -> I4891
A22: 10027445 | B22: 27488741 | C22: 89828.824 | D22: 89839.608 | F22: URGENT | G22: P38RSS | H22: TRANSFER FROM HOSPITAL | I22: HOME HEALTH CARE | J22: Other | K22: ENGLISH | L22: WIDOWED | M22: WHITE | P22: 0 | Q22: =_xlfn.XLOOKUP(A22, patients!A:A, patients!B:B) -> F | R22: =_xlfn.XLOOKUP(A22, patients!A:A, patients!C:C) -> 48 | S22: =IF(R22<30,"Under 30", IF(R22<=50,"30-50", IF(R22<=70,"50-70","70+"))) -> 30-50 | T22: =_xlfn.XLOOKUP(B22, diagnoses_icd!B:B, diagnoses_icd!D:D) -> 6822
A23: 10027445 | B23: 29163082 | C23: 88629.878 | D23: 88638.731 | F23: URGENT | G23: P509SB | H23: TRANSFER FROM HOSPITAL | I23: HOME HEALTH CARE | J23: Other | K23: ENGLISH | L23: WIDOWED | M23: WHITE | P23: 0 | Q23: =_xlfn.XLOOKUP(A23, patients!A:A, patients!B:B) -> F | R23: =_xlfn.XLOOKUP(A23, patients!A:A, patients!C:C) -> 48 | S23: =IF(R23<30,"Under 30", IF(R23<=50,"30-50", IF(R23<=70,"50-70","70+"))) -> 30-50 | T23: =_xlfn.XLOOKUP(B23, diagnoses_icd!B:B, diagnoses_icd!D:D) -> 4240
A24: 10015931 | B24: 22130791 | C24: 101257.91 | D24: 101262.59 | E24: 101262.59 | F24: URGENT | G24: P031HZ | H24: TRANSFER FROM HOSPITAL | I24: DIED | J24: Medicare | K24: ENGLISH | L24: MARRIED | M24: WHITE | P24: 1 | Q24: =_xlfn.XLOOKUP(A24, patients!A:A, patients!B:B) -> M | R24: =_xlfn.XLOOKUP(A24, patients!A:A, patients!C:C) -> 87 | S24: =IF(R24<30,"Under 30", IF(R24<=50,"30-50", IF(R24<=70,"50-70","70+"))) -> 70+ | T24: =_xlfn.XLOOKUP(B24, diagnoses_icd!B:B, diagnoses_icd!D:D) -> I4891
A25: 10036156 | B25: 28019404 | C25: 94051.203 | D25: 94053.631 | F25: URGENT | G25: P94V16 | H25: TRANSFER FROM HOSPITAL | I25: HOME | J25: Other | K25: ENGLISH | M25: UNKNOWN | P25: 0 | Q25: =_xlfn.XLOOKUP(A25, patients!A:A, patients!B:B) -> F | R25: =_xlfn.XLOOKUP(A25, patients!A:A, patients!C:C) -> 88 | S25: =IF(R25<30,"Under 30", IF(R25<=50,"30-50", IF(R25<=70,"50-70","70+"))) -> 70+ | T25: =_xlfn.XLOOKUP(B25, diagnoses_icd!B:B, diagnoses_icd!D:D) -> 2724
A26: 10021312 | B26: 25020332 | C26: 78026.022 | D26: 78028.733 | F26: URGENT | G26: P31A9M | H26: TRANSFER FROM HOSPITAL | I26: HOME | J26: Other | K26: ENGLISH | M26: UNKNOWN | P26: 0 | Q26: =_xlfn.XLOOKUP(A26, patients!A:A, patients!B:B) -> F | R26: =_xlfn.XLOOKUP(A26, patients!A:A, patients!C:C) -> 55 | S26: =IF(R26<30,"Under 30", IF(R26<=50,"30-50", IF(R26<=70,"50-70","70+"))) -> 50-70 | T26: =_xlfn.XLOOKUP(B26, diagnoses_icd!B:B, diagnoses_icd!D:D) -> C3402
A27: 10021312 | B27: 28829452 | C27: 78053.613 | D27: 78061.778 | F27: URGENT | G27: P72G4H | H27: TRANSFER FROM HOSPITAL | I27: ACUTE HOSPITAL | J27: Other | K27: ENGLISH | M27: UNKNOWN | P27: 0 | Q27: =_xlfn.XLOOKUP(A27, patients!A:A, patients!B:B) -> F | R27: =_xlfn.XLOOKUP(A27, patients!A:A, patients!C:C) -> 55 | S27: =IF(R27<30,"Under 30", IF(R27<=50,"30-50", IF(R27<=70,"50-70","70+"))) -> 50-70 | T27: =_xlfn.XLOOKUP(B27, diagnoses_icd!B:B, diagnoses_icd!D:D) -> G8929
A28: 10003400 | B28: 23559586 | C28: 86780.005 | D28: 86809.712 | E28: 86809.712 | F28: URGENT | G28: P99U21 | H28: TRANSFER FROM HOSPITAL | I28: DIED | J28: Medicare | K28: ENGLISH | L28: MARRIED | M28: BLACK/AFRICAN AMERICAN | P28: 1 | Q28: =_xlfn.XLOOKUP(A28, patients!A:A, patients!B:B) -> F | R28: =_xlfn.XLOOKUP(A28, patients!A:A, patients!C:C) -> 72 | S28: =IF(R28<30,"Under 30", IF(R28<=50,"30-50", IF(R28<=70,"50-70","70+"))) -> 70+ | T28: =_xlfn.XLOOKUP(B28, diagnoses_icd!B:B, diagnoses_icd!D:D) -> E669
A29: 10003400 | B29: 20214994 | C29: 86619.417 | D29: 86642.656 | F29: URGENT | G29: P60ZCO | H29: TRANSFER FROM SKILLED NURSING FACILITY | I29: CHRONIC/LONG TERM ACUTE CARE | J29: Medicare | K29: ENGLISH | L29: MARRIED | M29: BLACK/AFRICAN AMERICAN | P29: 0 | Q29: =_xlfn.XLOOKUP(A29, patients!A:A, patients!B:B) -> F | R29: =_xlfn.XLOOKUP(A29, patients!A:A, patients!C:C) -> 72 | S29: =IF(R29<30,"Under 30", IF(R29<=50,"30-50", IF(R29<=70,"50-70","70+"))) -> 70+ | T29: =_xlfn.XLOOKUP(B29, diagnoses_icd!B:B, diagnoses_icd!D:D) -> 99859
A30: 10023117 | B30: 24244087 | C30: 100236.98 | D30: 100241.66 | F30: URGENT | G30: P878WT | H30: TRANSFER FROM HOSPITAL | I30: HOME | J30: Medicare | K30: ENGLISH | L30: WIDOWED | M30: WHITE | N30: 100236.68 | O30: 100237.04 | P30: 0 | Q30: =_xlfn.XLOOKUP(A30, patients!A:A, patients!B:B) -> M | R30: =_xlfn.XLOOKUP(A30, patients!A:A, patients!C:C) -> 53 | S30: =IF(R30<30,"Under 30", IF(R30<=50,"30-50", IF(R30<=70,"50-70","70+"))) -> 50-70 | T30: =_xlfn.XLOOKUP(B30, diagnoses_icd!B:B, diagnoses_icd!D:D) -> V5866
A31: 10038992 | B31: 22797747 | C31: 104402.77 | D31: 104408.68 | F31: URGENT | G31: P534S8 | H31: TRANSFER FROM HOSPITAL | I31: HOME HEALTH CARE | J31: Medicare | K31: ENGLISH | L31: MARRIED | M31: UNKNOWN | P31: 0 | Q31: =_xlfn.XLOOKUP(A31, patients!A:A, patients!B:B) -> M | R31: =_xlfn.XLOOKUP(A31, patients!A:A, patients!C:C) -> 70 | S31: =IF(R31<30,"Under 30", IF(R31<=50,"30-50", IF(R31<=70,"50-70","70+"))) -> 50-70 | T31: =_xlfn.XLOOKUP(B31, diagnoses_icd!B:B, diagnoses_icd!D:D) -> 4239
A32: 10037975 | B32: 27617929 | C32: 104113.8 | D32: 104118.6 | E32: 104118.6 | F32: URGENT | G32: P17MK7 | H32: TRANSFER FROM HOSPITAL | I32: DIED | J32: Medicare | K32: ENGLISH | L32: MARRIED | M32: UNKNOWN | P32: 1 | Q32: =_xlfn.XLOOKUP(A32, patients!A:A, patients!B:B) -> M | R32: =_xlfn.XLOOKUP(A32, patients!A:A, patients!C:C) -> 60 | S32: =IF(R32<30,"Under 30", IF(R32<=50,"30-50", IF(R32<=70,"50-70","70+"))) -> 50-70 | T32: =_xlfn.XLOOKUP(B32, diagnoses_icd!B:B, diagnoses_icd!D:D) -> V667
A33: 10035185 | B33: 22580999 | C33: 80487.537 | D33: 80492.667 | F33: URGENT | G33: P41R5N | H33: TRANSFER FROM HOSPITAL | I33: HOME HEALTH CARE | J33: Other | K33: ENGLISH | L33: MARRIED | M33: WHITE | P33: 0 | Q33: =_xlfn.XLOOKUP(A33, patients!A:A, patients!B:B) -> M | R33: =_xlfn.XLOOKUP(A33, patients!A:A, patients!C:C) -> 70 | S33: =IF(R33<30,"Under 30", IF(R33<=50,"30-50", IF(R33<=70,"50-70","70+"))) -> 50-70 | T33: =_xlfn.XLOOKUP(B33, diagnoses_icd!B:B, diagnoses_icd!D:D) -> 4139
A34: 10002930 | B34: 28301173 | C34: 108577.82 | D34: 108584.5 | F34: URGENT | G34: P3763P | H34: INTERNAL TRANSFER TO OR FROM PSYCH | I34: HOME | J34: Medicare | K34: ENGLISH | L34: SINGLE | M34: BLACK/AFRICAN AMERICAN | P34: 0 | Q34: =_xlfn.XLOOKUP(A34, patients!A:A, patients!B:B) -> F | R34: =_xlfn.XLOOKUP(A34, patients!A:A, patients!C:C) -> 48 | S34: =IF(R34<30,"Under 30", IF(R34<=50,"30-50", IF(R34<=70,"50-70","70+"))) -> 30-50 | T34: =_xlfn.XLOOKUP(B34, diagnoses_icd!B:B, diagnoses_icd!D:D) -> V6284
A35: 10002930 | B35: 22733922 | C35: 108956.68 | D35: 108968.56 | F35: URGENT | G35: P3763P | H35: INTERNAL TRANSFER TO OR FROM PSYCH | I35: HOME | J35: Medicare | K35: ENGLISH | L35: SINGLE | M35: BLACK/AFRICAN AMERICAN | P35: 0 | Q35: =_xlfn.XLOOKUP(A35, patients!A:A, patients!B:B) -> F | R35: =_xlfn.XLOOKUP(A35, patients!A:A, patients!C:C) -> 48 | S35: =IF(R35<30,"Under 30", IF(R35<=50,"30-50", IF(R35<=70,"50-70","70+"))) -> 30-50 | T35: =_xlfn.XLOOKUP(B35, diagnoses_icd!B:B, diagnoses_icd!D:D) -> B20
A36: 10007795 | B36: 28477357 | C36: 86299.856 | D36: 86321.691 | F36: URGENT | G36: P172D4 | H36: TRANSFER FROM HOSPITAL | I36: CHRONIC/LONG TERM ACUTE CARE | J36: Medicare | K36: ENGLISH | L36: SINGLE | M36: WHITE | P36: 0 | Q36: =_xlfn.XLOOKUP(A36, patients!A:A, patients!B:B) -> F | R36: =_xlfn.XLOOKUP(A36, patients!A:A, patients!C:C) -> 53 | S36: =IF(R36<30,"Under 30", IF(R36<=50,"30-50", IF(R36<=70,"50-70","70+"))) -> 50-70 | T36: =_xlfn.XLOOKUP(B36, diagnoses_icd!B:B, diagnoses_icd!D:D) -> 5184
A37: 10007795 | B37: 25135483 | C37: 86323.847 | D37: 86331.717 | F37: URGENT | G37: P99LA7 | H37: TRANSFER FROM HOSPITAL | I37: REHAB | J37: Medicare | K37: ENGLISH | L37: SINGLE | M37: WHITE | P37: 0 | Q37: =_xlfn.XLOOKUP(A37, patients!A:A, patients!B:B) -> F | R37: =_xlfn.XLOOKUP(A37, patients!A:A, patients!C:C) -> 53 | S37: =IF(R37<30,"Under 30", IF(R37<=50,"30-50", IF(R37<=70,"50-70","70+"))) -> 50-70 | T37: =_xlfn.XLOOKUP(B37, diagnoses_icd!B:B, diagnoses_icd!D:D) -> 1179
A38: 10004733 | B38: 27411876 | C38: 100416.48 | D38: 100439.58 | F38: URGENT | G38: P48KFD | H38: TRANSFER FROM HOSPITAL | I38: HOME HEALTH CARE | J38: Medicaid | K38: ENGLISH | L38: SINGLE | M38: UNKNOWN | P38: 0 | Q38: =_xlfn.XLOOKUP(A38, patients!A:A, patients!B:B) -> M | R38: =_xlfn.XLOOKUP(A38, patients!A:A, patients!C:C) -> 51 | S38: =IF(R38<30,"Under 30", IF(R38<=50,"30-50", IF(R38<=70,"50-70","70+"))) -> 50-70 | T38: =_xlfn.XLOOKUP(B38, diagnoses_icd!B:B, diagnoses_icd!D:D) -> 5849
A39: 10021118 | B39: 24490144 | C39: 95649.84 | D39: 95657.667 | F39: URGENT | G39: P96FGV | H39: TRANSFER FROM HOSPITAL | I39: HOME HEALTH CARE | J39: Other | K39: ENGLISH | L39: MARRIED | M39: WHITE | P39: 0 | Q39: =_xlfn.XLOOKUP(A39, patients!A:A, patients!B:B) -> M | R39: =_xlfn.XLOOKUP(A39, patients!A:A, patients!C:C) -> 62 | S39: =IF(R39<30,"Under 30", IF(R39<=50,"30-50", IF(R39<=70,"50-70","70+"))) -> 50-70 | T39: =_xlfn.XLOOKUP(B39, diagnoses_icd!B:B, diagnoses_icd!D:D) -> I10
A40: 10006580 | B40: 24159665 | C40: 86786.458 | D40: 86791.559 | F40: ELECTIVE | G40: P76K54 | H40: PHYSICIAN REFERRAL | I40: HOME | J40: Medicaid | K40: ? | L40: MARRIED | M40: HISPANIC/LATINO - SALVADORAN | P40: 0 | Q40: =_xlfn.XLOOKUP(A40, patients!A:A, patients!B:B) -> F | R40: =_xlfn.XLOOKUP(A40, patients!A:A, patients!C:C) -> 63 | S40: =IF(R40<30,"Under 30", IF(R40<=50,"30-50", IF(R40<=70,"50-70","70+"))) -> 50-70 | T40: =_xlfn.XLOOKUP(B40, diagnoses_icd!B:B, diagnoses_icd!D:D) -> 2749
...

Sheet patients
A1: subject_id | B1: gender | C1: anchor_age | D1: anchor_year | E1: anchor_year_group | F1: dod
A2: 10014729 | B2: F | C2: 21 | D2: 2125 | E2: 2011 - 2013
A3: 10003400 | B3: F | C3: 72 | D3: 2134 | E3: 2011 - 2013 | F3: 86809
A4: 10002428 | B4: F | C4: 80 | D4: 2155 | E4: 2011 - 2013
A5: 10032725 | B5: F | C5: 38 | D5: 2143 | E5: 2011 - 2013 | F5: 88844
A6: 10027445 | B6: F | C6: 48 | D6: 2142 | E6: 2011 - 2013 | F6: 89891
A7: 10037928 | B7: F | C7: 78 | D7: 2175 | E7: 2011 - 2013
A8: 10001725 | B8: F | C8: 46 | D8: 2110 | E8: 2011 - 2013
A9: 10040025 | B9: F | C9: 64 | D9: 2143 | E9: 2011 - 2013 | F9: 90619
A10: 10008454 | B10: F | C10: 26 | D10: 2110 | E10: 2011 - 2013
A11: 10020640 | B11: F | C11: 91 | D11: 2153 | E11: 2011 - 2013 | F11: 92808
A12: 10014078 | B12: F | C12: 60 | D12: 2166 | E12: 2011 - 2013
A13: 10007795 | B13: F | C13: 53 | D13: 2136 | E13: 2011 - 2013
A14: 10001217 | B14: F | C14: 55 | D14: 2157 | E14: 2011 - 2013
A15: 10019172 | B15: F | C15: 63 | D15: 2118 | E15: 2011 - 2013
A16: 10039831 | B16: F | C16: 57 | D16: 2115 | E16: 2011 - 2013
A17: 10007928 | B17: F | C17: 59 | D17: 2129 | E17: 2011 - 2013
A18: 10019003 | B18: F | C18: 65 | D18: 2148 | E18: 2011 - 2013 | F18: 93475
A19: 10002930 | B19: F | C19: 48 | D19: 2193 | E19: 2011 - 2013 | F19: 110297
A20: 10010471 | B20: F | C20: 89 | D20: 2155 | E20: 2014 - 2016 | F20: 93479
A21: 10027602 | B21: F | C21: 71 | D21: 2201 | E21: 2014 - 2016
A22: 10031757 | B22: F | C22: 67 | D22: 2137 | E22: 2014 - 2016 | F22: 86868
A23: 10016742 | B23: F | C23: 58 | D23: 2178 | E23: 2014 - 2016
A24: 10039997 | B24: F | C24: 67 | D24: 2134 | E24: 2014 - 2016
A25: 10012853 | B25: F | C25: 91 | D25: 2175 | E25: 2014 - 2016
A26: 10000032 | B26: F | C26: 52 | D26: 2180 | E26: 2014 - 2016 | F26: 102522
A27: 10031404 | B27: F | C27: 82 | D27: 2113 | E27: 2014 - 2016
A28: 10029291 | B28: F | C28: 50 | D28: 2123 | E28: 2014 - 2016
A29: 10005909 | B29: F | C29: 40 | D29: 2144 | E29: 2014 - 2016
A30: 10039708 | B30: F | C30: 46 | D30: 2138 | E30: 2014 - 2016
A31: 10019568 | B31: F | C31: 59 | D31: 2120 | E31: 2014 - 2016
A32: 10020187 | B32: F | C32: 63 | D32: 2169 | E32: 2014 - 2016
A33: 10016810 | B33: F | C33: 66 | D33: 2185 | E33: 2014 - 2016
A34: 10038081 | B34: F | C34: 63 | D34: 2115 | E34: 2014 - 2016 | F34: 78813
A35: 10021312 | B35: F | C35: 55 | D35: 2113 | E35: 2014 - 2016
A36: 10006580 | B36: F | C36: 63 | D36: 2137 | E36: 2014 - 2016
A37: 10010867 | B37: F | C37: 28 | D37: 2147 | E37: 2014 - 2016
A38: 10020786 | B38: F | C38: 86 | D38: 2189 | E38: 2014 - 2016
A39: 10020306 | B39: F | C39: 74 | D39: 2129 | E39: 2014 - 2016
A40: 10023239 | B40: F | C40: 29 | D40: 2137 | E40: 2014 - 2016
...

Sheet Dashboard
A1: Healthcare EHR Analysis Dashboard
A5: Total Admissions | C5: Total Deaths | E5: Mortality Rate
A6: =COUNTA(admissions!B:B) -> 276 | C6: =SUM(admissions[hospital_expire_flag]) -> 15 | E6: =AVERAGE(admissions[hospital_expire_flag]) -> 0.054545455
A22: Higher mortality observed in patients aged 70+, indicating increased risk with age.
